<?xml version="1.0" encoding="UTF-8"?>
<!-- Generated by org.testng.reporters.JUnitReportReporter -->
<testsuite skipped="8" hostname="Ragu-PC" name="com.mytryanalizer.org.MyRetrySample" tests="10" failures="2" timestamp="2020-01-08T12:31:37 IST" time="0.104" errors="0">
  <testcase name="test1" time="0.002" classname="com.mytryanalizer.org.MyRetrySample">
    <skipped/>
  </testcase> <!-- test1 -->
  <testcase name="test2" time="0.001" classname="com.mytryanalizer.org.MyRetrySample">
    <skipped/>
  </testcase> <!-- test2 -->
  <testcase name="test2" time="0.059" classname="com.mytryanalizer.org.MyRetrySample">
    <skipped/>
  </testcase> <!-- test2 -->
  <testcase name="test1" time="0.003" classname="com.mytryanalizer.org.MyRetrySample">
    <failure type="java.lang.AssertionError" message="expected [sffss] but found [a]">
      <![CDATA[java.lang.AssertionError: expected [sffss] but found [a]
at org.testng.Assert.fail(Assert.java:97)
at org.testng.Assert.assertEqualsImpl(Assert.java:136)
at org.testng.Assert.assertEquals(Assert.java:118)
at org.testng.Assert.assertEquals(Assert.java:575)
at org.testng.Assert.assertEquals(Assert.java:585)
at com.mytryanalizer.org.MyRetrySample.test1(MyRetrySample.java:10)
at sun.reflect.NativeMethodAccessorImpl.invoke0(Native Method)
at sun.reflect.NativeMethodAccessorImpl.invoke(Unknown Source)
at sun.reflect.DelegatingMethodAccessorImpl.invoke(Unknown Source)
at java.lang.reflect.Method.invoke(Unknown Source)
at org.testng.internal.MethodInvocationHelper.invokeMethod(MethodInvocationHelper.java:133)
at org.testng.internal.TestInvoker.invokeMethod(TestInvoker.java:584)
at org.testng.internal.TestInvoker.retryFailed(TestInvoker.java:204)
at org.testng.internal.MethodRunner.runInSequence(MethodRunner.java:58)
at org.testng.internal.TestInvoker$MethodInvocationAgent.invoke(TestInvoker.java:804)
at org.testng.internal.TestInvoker.invokeTestMethods(TestInvoker.java:145)
at org.testng.internal.TestMethodWorker.invokeTestMethods(TestMethodWorker.java:146)
at org.testng.internal.TestMethodWorker.run(TestMethodWorker.java:128)
at java.util.ArrayList.forEach(Unknown Source)
at org.testng.TestRunner.privateRun(TestRunner.java:770)
at org.testng.TestRunner.run(TestRunner.java:591)
at org.testng.SuiteRunner.runTest(SuiteRunner.java:402)
at org.testng.SuiteRunner.access$000(SuiteRunner.java:41)
at org.testng.SuiteRunner$SuiteWorker.run(SuiteRunner.java:443)
at org.testng.internal.thread.ThreadUtil.lambda$execute$0(ThreadUtil.java:67)
at java.util.concurrent.FutureTask.run(Unknown Source)
at java.util.concurrent.ThreadPoolExecutor.runWorker(Unknown Source)
at java.util.concurrent.ThreadPoolExecutor$Worker.run(Unknown Source)
at java.lang.Thread.run(Unknown Source)
]]>
    </failure>
  </testcase> <!-- test1 -->
  <testcase name="test1" time="0.001" classname="com.mytryanalizer.org.MyRetrySample">
    <skipped/>
  </testcase> <!-- test1 -->
  <testcase name="test2" time="0.018" classname="com.mytryanalizer.org.MyRetrySample">
    <failure type="java.lang.AssertionError" message="expected [aabbaa] but found [b]">
      <![CDATA[java.lang.AssertionError: expected [aabbaa] but found [b]
at org.testng.Assert.fail(Assert.java:97)
at org.testng.Assert.assertEqualsImpl(Assert.java:136)
at org.testng.Assert.assertEquals(Assert.java:118)
at org.testng.Assert.assertEquals(Assert.java:575)
at org.testng.Assert.assertEquals(Assert.java:585)
at com.mytryanalizer.org.MyRetrySample.test2(MyRetrySample.java:15)
at sun.reflect.NativeMethodAccessorImpl.invoke0(Native Method)
at sun.reflect.NativeMethodAccessorImpl.invoke(Unknown Source)
at sun.reflect.DelegatingMethodAccessorImpl.invoke(Unknown Source)
at java.lang.reflect.Method.invoke(Unknown Source)
at org.testng.internal.MethodInvocationHelper.invokeMethod(MethodInvocationHelper.java:133)
at org.testng.internal.TestInvoker.invokeMethod(TestInvoker.java:584)
at org.testng.internal.TestInvoker.retryFailed(TestInvoker.java:204)
at org.testng.internal.MethodRunner.runInSequence(MethodRunner.java:58)
at org.testng.internal.TestInvoker$MethodInvocationAgent.invoke(TestInvoker.java:804)
at org.testng.internal.TestInvoker.invokeTestMethods(TestInvoker.java:145)
at org.testng.internal.TestMethodWorker.invokeTestMethods(TestMethodWorker.java:146)
at org.testng.internal.TestMethodWorker.run(TestMethodWorker.java:128)
at java.util.ArrayList.forEach(Unknown Source)
at org.testng.TestRunner.privateRun(TestRunner.java:770)
at org.testng.TestRunner.run(TestRunner.java:591)
at org.testng.SuiteRunner.runTest(SuiteRunner.java:402)
at org.testng.SuiteRunner.access$000(SuiteRunner.java:41)
at org.testng.SuiteRunner$SuiteWorker.run(SuiteRunner.java:443)
at org.testng.internal.thread.ThreadUtil.lambda$execute$0(ThreadUtil.java:67)
at java.util.concurrent.FutureTask.run(Unknown Source)
at java.util.concurrent.ThreadPoolExecutor.runWorker(Unknown Source)
at java.util.concurrent.ThreadPoolExecutor$Worker.run(Unknown Source)
at java.lang.Thread.run(Unknown Source)
]]>
    </failure>
  </testcase> <!-- test2 -->
  <testcase name="test2" time="0.004" classname="com.mytryanalizer.org.MyRetrySample">
    <skipped/>
  </testcase> <!-- test2 -->
  <testcase name="test1" time="0.001" classname="com.mytryanalizer.org.MyRetrySample">
    <skipped/>
  </testcase> <!-- test1 -->
  <testcase name="test1" time="0.001" classname="com.mytryanalizer.org.MyRetrySample">
    <skipped/>
  </testcase> <!-- test1 -->
  <testcase name="test2" time="0.014" classname="com.mytryanalizer.org.MyRetrySample">
    <skipped/>
  </testcase> <!-- test2 -->
</testsuite> <!-- com.mytryanalizer.org.MyRetrySample -->
